Workbook

Sheet TỔNG HỢP KHKD 2025
A1: CÔNG TY CỔ PHẦN ONE CAPITAL HOSPITALITY
A3: KẾ HOẠCH SẢN XUẤT KINH DOANH NĂM 2026 - MẸ | F3: =F111+F112-F113-F118 -> 0 | G3: =G111+G112-G113-G118 -> 0 | H3: =H111+H112-H113-H118 -> 0
E5: 4
A6: Lọc | C6: TÊN CHỈ TIÊU | D6: THỰC HIỆN | V6: KẾ HOẠCH | AO6: Tỷ lệ % 2025/ 2024 | AP6: THỰC HIỆN KH SXKD 2025 | BG6: KH SXKD 2026 | BX6: TH SXKD 2026 | CO6: CL | CQ6: CL25/24 | CR6: CL 26/25
D7: NĂM 2024 | E7: Lũy kế 2024 | F7: TH-2024-01 | G7: TH-2024-02 | H7: TH-2024-03 | I7: TH-2024-04 | J7: TH-2024-05 | K7: TH-2024-06 | L7: TH-2024-07 | M7: TH-2024-08 | N7: TH-2024-09 | O7: TH-2024-10 | P7: TH-2024-11 | Q7: TH-2024-12 | R7: QUÝ I | S7: QUÝ II | T7: QUÝ III | U7: QUÝ IV | V7: Năm 2025 | W7: Lũy kế KH 2025 | X7: KH-2025-01 | Y7: KH-2025-02 | Z7: KH-2025-03 | AA7: KH-2025-04 | AB7: KH-2025-05 | AC7: KH-2025-06 | AD7: KH-2025-07 | AE7: KH-2025-08 | AF7: KH-2025-09 | AG7: KH-2025-10 | AH7: KH-2025-11 | AI7: KH-2025-12 | AJ7: Ghi chú | AK7: QUÝ I | AL7: QUÝ II | AM7: QUÝ III | AN7: QUÝ IV | AP7: Lũy kế thực hiện năm 2025 | AQ7: TH-2025-01 | AR7: TH-2025-02 | AS7: TH-2025-03 | AT7: TH-2025-04 | AU7: TH-2025-05 | AV7: TH-2025-06 | AW7: TH-2025-07 | AX7: TH-2025-08 | AY7: TH-2025-09 | AZ7: TH-2025-10 | BA7: TH-2025-11 | BB7: TH-2025-12 | BC7: QUÝ I | BD7: QUÝ II | BE7: QUÝ III | BF7: QUÝ IV | BG7: Lũy kế KH năm 2026 | BH7: KH-2026-01 | BI7: KH-2026-02 | BJ7: KH-2026-03 | BK7: KH-2026-04 | BL7: KH-2026-05 | BM7: KH-2026-06 | BN7: KH-2026-07 | BO7: KH-2026-08 | BP7: KH-2026-09 | BQ7: KH-2026-10 | BR7: KH-2026-11 | BS7: KH-2026-12 | BT7: QUÝ I | BU7: QUÝ II | BV7: QUÝ III | BW7: QUÝ IV | BX7: Lũy kế TH năm 2026 | BY7: TH-2026-01 | BZ7: TH-2026-02 | CA7: TH-2026-03 | CB7: TH-2026-04 | CC7: TH-2026-05 | CD7: TH-2026-06 | CE7: TH-2026-07 | CF7: TH-2026-08 | CG7: TH-2026-09 | CH7: TH-2026-10 | CI7: TH-2026-11 | CJ7: TH-2026-12 | CK7: QUÝ I | CL7: QUÝ II | CM7: QUÝ III | CN7: QUÝ IV | CQ7: 1 | CR7: 2 | CS7: 3 | CT7: 4 | CU7: 5 | CV7: 6 | CW7: 7 | CX7: 8 | CY7: 9 | CZ7: 10 | DA7: 11 | DB7: 12
A8: =IF((E8+V8)<>0, "in", "ẩn") -> in | C8: 1. Doanh thu bán hàng và cung cấp dịch vụ | D8: 251738021480 | E8: 28074834024 | F8: 8625085726 | G8: 3123216088 | H8: 6873593666 | I8: 9452938544 | J8: 12187684327 | K8: 14572553903 | L8: 57110446262 | M8: 81979724061 | N8: 27445755387 | O8: 10025415221 | P8: 8751235578 | Q8: 11590372717 | R8: 18621895480 | S8: 36213176774 | T8: 166535925710 | U8: 30367023516 | V8: 2.8388901e+11 | W8: 2.8388901e+11 | X8: 1.3890605e+10 | Y8: 6.7959294e+09 | Z8: 8.7641859e+09 | AA8: 1.1350535e+10 | AB8: 1.2053007e+10 | AC8: 1.1460245e+10 | AD8: 5.7113188e+10 | AE8: 7.8874245e+10 | AF8: 5.4010531e+10 | AG8: 1.0638425e+10 | AH8: 9.1471312e+09 | AI8: 9.7909863e+09 | AK8: 2.945072e+10 | AL8: 3.4863787e+10 | AM8: 1.8999796e+11 | AN8: 2.9576543e+10 | AO8: 1.1277161 | AP8: 290852178198 | AQ8: 13797963587 | AR8: 6659874230 | AS8: 9019405457 | AT8: 11016654074 | AU8: 11810186322 | AV8: 10390531914 | AW8: 41024125459 | AX8: 73871522687 | AY8: 80278102476 | AZ8: 11306829647 | BA8: 8531991581 | BB8: 13144990764 | BC8: 29477243274 | BD8: 33217372310 | BE8: 195173750622 | BF8: 32983811992 | BG8: 303818820953 | BH8: 7430996486 | BI8: 8583276880 | BJ8: 10174546674 | BK8: 12180080870 | BL8: 11934279308 | BM8: 12940754388 | BN8: 49533062151 | BO8: 84816242627 | BP8: 72959961527 | BQ8: 12101915370 | BR8: 8966700330 | BS8: 12197004342 | BT8: 26188820040 | BU8: 37055114566 | BV8: 207309266305 | BW8: 33265620042 | BX8: 8054506984 | BY8: 8054506984 | CK8: 8054506984 | CO8: =BG8-AP8 -> 12966642755 | CP8: =IF(AP8<>0,CO8/AP8,"") -> 0.044581556 | CQ8: =AP8/D8 -> 1.1553764 | CR8: =BG8/AP8 -> 1.0445816
A9: =IF((E9+V9)<>0, "in", "ẩn") -> in | C9: - Doanh thu bán hàng cho Givral | D9: 76063779652 | E9: 17405522750 | F9: 6054371544 | G9: 1592962480 | H9: 4857041894 | I9: 4901146832 | J9: 5698773042 | K9: 5610862091 | L9: 6421054729 | M9: 11310822536 | N9: 7134202337 | O9: 7576579001 | P9: 6182501598 | Q9: 8723461568 | R9: 12504375918 | S9: 16210781965 | T9: 24866079602 | U9: 22482542167 | V9: 8.1184501e+10 | W9: 8.1184501e+10 | X9: 4.9229248e+09 | Y9: 4.848335e+09 | Z9: 6.1163611e+09 | AA9: 5.9671816e+09 | AB9: 5.9671816e+09 | AC9: 5.5942327e+09 | AD9: 6.2537058e+09 | AE9: 1.150224e+10 | AF9: 8.9780228e+09 | AG9: 6.7130793e+09 | AH9: 6.3401304e+09 | AI9: 7.9811054e+09 | AK9: 1.5887621e+10 | AL9: 1.7528596e+10 | AM9: 2.6733969e+10 | AN9: 2.1034315e+10 | AO9: 1.0673214 | AP9: 81373286457 | AQ9: 4830283572 | AR9: 4712279910 | AS9: 7072764093 | AT9: 5408472034 | AU9: 6016204962 | AV9: 4801915961 | AW9: 6176217612 | AX9: 9149002663 | AY9: 7924417131 | AZ9: 8578469977 | BA9: 6649639235 | BB9: 10053619307 | BC9: 16615327575 | BD9: 16226592957 | BE9: 23249637406 | BF9: 25281728519 | BG9: 83706619216 | BH9: 5605574756 | BI9: 2684922792 | BJ9: 7207167543 | BK9: 5605574756 | BL9: 5841303928 | BM9: 5605574756 | BN9: 7569865528 | BO9: 10096362694 | BP9: 9748914264 | BQ9: 8007963937 | BR9: 6123837539 | BS9: 9609556723 | BT9: 15497665091 | BU9: 17052453440 | BV9: 27415142486 | BW9: 23741358199 | BX9: 6239085254 | BY9: 6239085254 | CK9: 6239085254 | CO9: =BG9-AP9 -> 2333332759 | CP9: =IF(AP9<>0,CO9/AP9,"") -> 0.028674432 | CQ9: =AP9/D9 -> 1.0698034 | CR9: =BG9/AP9 -> 1.0286744
A10: =IF((E10+V10)<>0, "in", "ẩn") -> in | C10: + DT - Givral - Daily | D10: 70181718652 | E10: 17405522750 | F10: 6054371544 | G10: 1592962480 | H10: 4857041894 | I10: 4901146832 | J10: 5698773042 | K10: 5209021091 | L10: 6214276729 | M10: 7336395536 | N10: 5835187337 | O10: 7576579001 | P10: 6182501598 | Q10: 8723461568 | R10: 12504375918 | S10: 15808940965 | T10: 19385859602 | U10: 22482542167 | V10: 7.458977e+10 | W10: 7.458977e+10 | X10: 4.9229248e+09 | Y10: 4.848335e+09 | Z10: 6.1163611e+09 | AA10: 5.9671816e+09 | AB10: 5.9671816e+09 | AC10: 5.5942327e+09 | AD10: 5.5942327e+09 | AE10: 8.2048747e+09 | AF10: 6.3401304e+09 | AG10: 6.7130793e+09 | AH10: 6.3401304e+09 | AI10: 7.9811054e+09 | AK10: 1.5887621e+10 | AL10: 1.7528596e+10 | AM10: 2.0139238e+10 | AN10: 2.1034315e+10 | AO10: 1.0628091 | AP10: 77856340057 | AQ10: 4830283572 | AR10: 4712279910 | AS10: 7072764093 | AT10: 5408472034 | AU10: 6016204962 | AV10: 4801915961 | AW10: 5841597612 | AX10: 7855386163 | AY10: 6035707231 | AZ10: 8578469977 | BA10: 6649639235 | BB10: 10053619307 | BC10: 16615327575 | BD10: 16226592957 | BE10: 19732691006 | BF10: 25281728519 | BG10: 80079639368 | BH10: 5605574756 | BI10: 2684922792 | BJ10: 7207167543 | BK10: 5605574756 | BL10: 5841303928 | BM10: 5605574756 | BN10: 7207167543 | BO10: 8573031158 | BP10: 8007963937 | BQ10: 8007963937 | BR10: 6123837539 | BS10: 9609556723 | BT10: 15497665091 | BU10: 17052453440 | BV10: 23788162638 | BW10: 23741358199 | BX10: 6239085254 | BY10: 6239085254 | CK10: 6239085254 | CO10: =BG10-AP10 -> 2223299311 | CP10: =IF(AP10<>0,CO10/AP10,"") -> 0.028556432 | CQ10: =AP10/D10 -> 1.1093536 | CR10: =BG10/AP10 -> 1.0285564
A11: =IF((E11+V11)<>0, "in", "ẩn") -> in | C11: + DT - Givral - Trung thu | D11: 5882061000 | E11: 0 | F11: 0 | G11: 0 | H11: 0 | I11: 0 | J11: 0 | K11: 401841000 | L11: 206778000 | M11: 3974427000 | N11: 1299015000 | O11: 0 | P11: 0 | Q11: 0 | R11: 0 | S11: 401841000 | T11: 5480220000 | U11: 0 | V11: 6.5947308e+09 | W11: 6.5947308e+09 | X11: 0 | Y11: 0 | Z11: 0 | AA11: 0 | AB11: 0 | AC11: 0 | AD11: 6.5947308e+08 | AE11: 3.2973654e+09 | AF11: 2.6378923e+09 | AG11: 0 | AH11: 0 | AI11: 0 | AK11: 0 | AL11: 0 | AM11: 6.5947308e+09 | AN11: 0 | AO11: 1.1211599 | AP11: 3516946400 | AW11: 334620000 | AX11: 1293616500 | AY11: 1888709900 | BC11: 0 | BD11: 0 | BE11: 3516946400 | BF11: 0 | BG11: 3626979848 | BH11: 0 | BI11: 0 | BJ11: 0 | BK11: 0 | BL11: 0 | BM11: 362697985 | BN11: 1523331536 | BO11: 1740950327 | BP11: 0 | BQ11: 0 | BR11: 0 | BS11: 0 | BT11: 0 | BU11: 362697985 | BV11: 3264281863 | BW11: 0 | BX11: 0 | CO11: =BG11-AP11 -> 110033448 | CP11: =IF(AP11<>0,CO11/AP11,"") -> 0.031286643 | CQ11: =AP11/D11 -> 0.59791056 | CR11: =BG11/AP11 -> 1.0312866
A12: =IF((E12+V12)<>0, "in", "ẩn") -> in | C12: - Doanh thu bán hàng cho Kem TT | D12: 174389248075 | E12: 10669311274 | F12: 2570714182 | G12: 1530253608 | H12: 2016551772 | I12: 4551791712 | J12: 6488911285 | K12: 8928464540 | L12: 50669391533 | M12: 70668901525 | N12: 20293738278 | O12: 2448836220 | P12: 2558733980 | Q12: 1662959440 | R12: 6117519562 | S12: 19969167537 | T12: 141632031336 | U12: 6670529640 | V12: 1.9570349e+11 | W12: 1.9570349e+11 | X12: 2374483990 | Y12: 1761977800 | Z12: 2.5509423e+09 | AA12: 5.3833532e+09 | AB12: 6.0858257e+09 | AC12: 5.824115e+09 | AD12: 5.0859482e+10 | AE12: 6.7372005e+10 | AF12: 4.4988665e+10 | AG12: 3.9253457e+09 | AH12: 2.8070008e+09 | AI12: 1.7702943e+09 | AK12: 6.6874041e+09 | AL12: 1.7293294e+10 | AM12: 1.6322015e+11 | AN12: 8.5026408e+09 | AO12: 1.1222222 | AP12: 201201615196 | AQ12: 2374483990 | AR12: 1761977800 | AS12: 1849758900 | AT12: 5568182040 | AU12: 5763981360 | AV12: 5407600440 | AW12: 34827907847 | AX12: 64702520024 | AY12: 72239489139 | AZ12: 2718359670 | BA12: 1871237346 | BB12: 2116116640 | BC12: 5986220690 | BD12: 16739763840 | BE12: 171769917010 | BF12: 6705713656 | BG12: 215602968715 | BH12: 1815421730 | BI12: 1927707792 | BJ12: 2884808421 | BK12: 6554506114 | BL12: 6082975380 | BM12: 7205062568 | BN12: 41933196623 | BO12: 74699879933 | BP12: 63101560867 | BQ12: 4083951433 | BR12: 2832862791 | BS12: 2481035063 | BT12: 6627937943 | BU12: 19842544062 | BV12: 179734637423 | BW12: 9397849287 | BX12: 1815421730 | BY12: 1815421730 | CK12: 1815421730 | CO12: =BG12-AP12 -> 14401353519 | CP12: =IF(AP12<>0,CO12/AP12,"") -> 0.071576729 | CQ12: =AP12/D12 -> 1.1537501 | CR12: =BG12/AP12 -> 1.0715767
A13: =IF((E13+V13)<>0, "in", "ẩn") -> in | C13: + DT - KTT - Daily | D13: 41816349253 | E13: 10669311274 | F13: 2570714182 | G13: 1530253608 | H13: 2016551772 | I13: 4551791712 | J13: 6488911285 | K13: 4060850756 | L13: 6721621934 | M13: 4475550994 | N13: 2729573370 | O13: 2448836220 | P13: 2558733980 | Q13: 1662959440 | R13: 6117519562 | S13: 15101553753 | T13: 13926746298 | U13: 6670529640 | V13: 4.7876034e+10 | W13: 4.7876034e+10 | X13: 2374483990 | Y13: 1761977800 | Z13: 2.5509423e+09 | AA13: 5.3833532e+09 | AB13: 6.0858257e+09 | AC13: 5.824115e+09 | AD13: 6.7620527e+09 | AE13: 5.2343116e+09 | AF13: 3.3963307e+09 | AG13: 3.9253457e+09 | AH13: 2.8070008e+09 | AI13: 1.7702943e+09 | AK13: 6.6874041e+09 | AL13: 1.7293294e+10 | AM13: 1.5392695e+10 | AN13: 8.5026408e+09 | AO13: 1.1449118 | AP13: 45036083653 | AQ13: 2374483990 | AR13: 1761977800 | AS13: 1849758900 | AT13: 5568182040 | AU13: 5763981360 | AV13: 5407600440 | AW13: 5334000711 | AX13: 5800635116 | AY13: 4480430840 | AZ13: 2707678470 | BA13: 1871237346 | BB13: 2116116640 | BC13: 5986220690 | BD13: 16739763840 | BE13: 15615066667 | BF13: 6695032456 | BG13: 55546294310 | BH13: 1815421730 | BI13: 1927707792 | BJ13: 2884808421 | BK13: 6554506114 | BL13: 6082975380 | BM13: 7205062568 | BN13: 6989093106 | BO13: 7476076683 | BP13: 5212793229 | BQ13: 4083951433 | BR13: 2832862791 | BS13: 2481035063 | BT13: 6627937943 | BU13: 19842544062 | BV13: 19677963018 | BW13: 9397849287 | BX13: 1815421730 | BY13: 1815421730 | CK13: 1815421730 | CO13: =BG13-AP13 -> 10510210657 | CP13: =IF(AP13<>0,CO13/AP13,"") -> 0.2333731 | CQ13: =AP13/D13 -> 1.076997 | CR13: =BG13/AP13 -> 1.2333731
A14: =IF((E14+V14)<>0, "in", "ẩn") -> in | C14: + DT - KTT - Trung thu | D14: 132572898822 | E14: 0 | F14: 0 | G14: 0 | H14: 0 | I14: 0 | J14: 0 | K14: 4867613784 | L14: 43947769599 | M14: 66193350531 | N14: 17564164908 | O14: 0 | P14: 0 | Q14: 0 | R14: 0 | S14: 4867613784 | T14: 127705285038 | U14: 0 | V14: 1.4782746e+11 | W14: 1.4782746e+11 | X14: 0 | Y14: 0 | Z14: 0 | AA14: 0 | AB14: 0 | AC14: 0 | AD14: 4.4097429e+10 | AE14: 6.2137693e+10 | AF14: 4.1592334e+10 | AG14: 0 | AH14: 0 | AI14: 0 | AK14: 0 | AL14: 0 | AM14: 1.4782746e+11 | AN14: 0 | AO14: 1.1150654 | AP14: 156165531543 | AW14: 29493907136 | AX14: 58901884908 | AY14: 67759058299 | AZ14: 10681200 | BC14: 0 | BD14: 0 | BE14: 156154850343 | BF14: 10681200 | BG14: 160056674405 | BH14: 0 | BI14: 0 | BJ14: 0 | BK14: 0 | BL14: 0 | BM14: 0 | BN14: 34944103517 | BO14: 67223803250 | BP14: 57888767638 | BQ14: 0 | BR14: 0 | BS14: 0 | BT14: 0 | BU14: 0 | BV14: 160056674405 | BW14: 0 | BX14: 0 | CO14: =BG14-AP14 -> 3891142862 | CP14: =IF(AP14<>0,CO14/AP14,"") -> 0.024916784 | CQ14: =AP14/D14 -> 1.1779597 | CR14: =BG14/AP14 -> 1.0249168
A15: =IF((E15+V15)<>0, "in", "ẩn") -> in | C15: - Doanh thu hoạt động thương mại khác | D15: 846947640 | E15: 0 | F15: 0 | G15: 0 | H15: 0 | I15: 0 | J15: 0 | K15: 0 | L15: 0 | M15: 0 | N15: 0 | O15: 0 | P15: 0 | Q15: 846947640 | R15: 0 | S15: 0 | T15: 0 | U15: 846947640 | V15: 6693890507 | W15: 6693890507 | X15: 6508273987 | Y15: 185616520 | Z15: 0 | AA15: 0 | AB15: 0 | AC15: 0 | AD15: 0 | AE15: 0 | AF15: 0 | AG15: 0 | AH15: 0 | AI15: 0 | AK15: 6693890507 | AL15: 0 | AM15: 0 | AN15: 0 | AO15: 7.903547 | AP15: 6693890507 | AQ15: 6508273987 | AR15: 185616520 | AS15: 0 | AT15: 0 | AU15: 0 | AV15: 0 | AW15: 0 | AX15: 0 | AY15: 0 | AZ15: 0 | BA15: 0 | BB15: 0 | BC15: 6693890507 | BD15: 0 | BE15: 0 | BF15: 0 | BG15: 3960646296 | BH15: 0 | BI15: 3960646296 | BJ15: 0 | BK15: 0 | BL15: 0 | BM15: 0 | BN15: 0 | BO15: 0 | BP15: 0 | BQ15: 0 | BR15: 0 | BS15: 0 | BT15: 3960646296 | BU15: 0 | BV15: 0 | BW15: 0 | BX15: 0 | BY15: 0 | CK15: 0 | CO15: =BG15-AP15 -> -2733244211 | CP15: =IF(AP15<>0,CO15/AP15,"") -> -0.40831923 | CQ15: =AP15/D15 -> 7.903547 | CR15: =BG15/AP15 -> 0.59168077
A16: =IF((E16+V16)<>0, "in", "ẩn") -> in | C16: + Bánh chưng truyền thống cho Kem TT | D16: 846947640 | E16: 0 | F16: 0 | G16: 0 | H16: 0 | I16: 0 | J16: 0 | K16: 0 | L16: 0 | M16: 0 | N16: 0 | O16: 0 | P16: 0 | Q16: 846947640 | R16: 0 | S16: 0 | T16: 0 | U16: 846947640 | V16: 3246143200 | W16: 3246143200 | X16: 3088804480 | Y16: 157338720 | Z16: 0 | AA16: 0 | AB16: 0 | AC16: 0 | AD16: 0 | AE16: 0 | AF16: 0 | AG16: 0 | AH16: 0 | AI16: 0 | AK16: 3246143200 | AL16: 0 | AM16: 0 | AN16: 0 | AO16: 3.8327555 | AP16: 3246143200 | AQ16: 3088804480 | AR16: 157338720 | BC16: 3246143200 | BD16: 0 | BE16: 0 | BF16: 0 | BG16: 0 | BT16: 0 | BU16: 0 | BV16: 0 | BW16: 0 | BX16: 0 | CO16: =BG16-AP16 -> -3246143200 | CP16: =IF(AP16<>0,CO16/AP16,"") -> -1 | CQ16: =AP16/D16 -> 3.8327555 | CR16: =BG16/AP16 -> 0
A17: =IF((E17+V17)<>0, "in", "ẩn") -> in | C17: + Hộp quà tết cho vietinbank và khách lẻ | D17: 0 | E17: 0 | F17: 0 | G17: 0 | H17: 0 | I17: 0 | J17: 0 | K17: 0 | L17: 0 | M17: 0 | N17: 0 | O17: 0 | P17: 0 | Q17: 0 | R17: 0 | S17: 0 | T17: 0 | U17: 0 | V17: 3447747307 | W17: 3447747307 | X17: 3419469507 | Y17: 28277800 | Z17: 0 | AA17: 0 | AB17: 0 | AC17: 0 | AD17: 0 | AE17: 0 | AF17: 0 | AG17: 0 | AH17: 0 | AI17: 0 | AK17: 3447747307 | AL17: 0 | AM17: 0 | AN17: 0 | AP17: 3447747307 | AQ17: 3419469507 | AR17: 28277800 | BC17: 3447747307 | BD17: 0 | BE17: 0 | BF17: 0 | BG17: 3960646296 | BH17: 0 | BI17: 3960646296 | BJ17: 0 | BK17: 0 | BL17: 0 | BM17: 0 | BN17: 0 | BO17: 0 | BP17: 0 | BQ17: 0 | BR17: 0 | BS17: 0 | BT17: 3960646296 | BU17: 0 | BV17: 0 | BW17: 0 | BX17: 0 | BY17: 0 | CK17: 0 | CO17: =BG17-AP17 -> 512898989 | CP17: =IF(AP17<>0,CO17/AP17,"") -> 0.14876351 | CQ17: =AP17/D17 -> #DIV/0! | CR17: =BG17/AP17 -> 1.1487635
A18: =IF((E18+V18)<>0, "in", "ẩn") -> in | C18: - Doanh thu liên quan đến condotel | D18: 127907224 | E18: 0 | F18: 0 | G18: 0 | H18: 0 | I18: 0 | J18: 0 | K18: 33227272 | L18: 20000000 | M18: 0 | N18: 17814772 | O18: 0 | P18: 10000000 | Q18: 46865180 | R18: 0 | S18: 33227272 | T18: 37814772 | U18: 56865180 | V18: 2.222096e+08 | W18: 2.222096e+08 | X18: 0 | Y18: 0 | Z18: 96882464 | AA18: 0 | AB18: 0 | AC18: 41897453 | AD18: 0 | AE18: 0 | AF18: 43843045 | AG18: 0 | AH18: 0 | AI18: 39586634 | AK18: 96882464 | AL18: 41897453 | AM18: 43843045 | AN18: 39586634 | AO18: 1.7372717 | AP18: 613915665 | AQ18: 0 | AR18: 0 | AS18: 96882464 | AT18: 40000000 | AU18: 30000000 | AV18: 181015513 | AW18: 20000000 | AX18: 20000000 | AY18: 114196206 | AZ18: 10000000 | BA18: 0 | BB18: 101821482 | BC18: 96882464 | BD18: 251015513 | BE18: 154196206 | BF18: 111821482 | BG18: 548586726 | BH18: 10000000 | BI18: 10000000 | BJ18: 82570710 | BK18: 20000000 | BL18: 10000000 | BM18: 130117064 | BN18: 30000000 | BO18: 20000000 | BP18: 109486396 | BQ18: 10000000 | BR18: 10000000 | BS18: 106412556 | BT18: 102570710 | BU18: 160117064 | BV18: 159486396 | BW18: 126412556 | BX18: 0 | BY18: 0 | CK18: 0 | CO18: =BG18-AP18 -> -65328939 | CP18: =IF(AP18<>0,CO18/AP18,"") -> -0.10641354 | CQ18: =AP18/D18 -> 4.799695 | CR18: =BG18/AP18 -> 0.89358646
A19: =IF((E19+V19)<>0, "in", "ẩn") -> ẩn | C19: + Doanh thu chuyển nhượng condotel | D19: 0 | E19: 0 | F19: 0 | G19: 0 | H19: 0 | I19: 0 | J19: 0 | K19: 0 | L19: 0 | M19: 0 | N19: 0 | O19: 0 | R19: 0 | S19: 0 | T19: 0 | U19: 0 | V19: 0 | W19: 0 | AK19: 0 | AL19: 0 | AM19: 0 | AN19: 0 | AP19: 0 | AQ19: 0 | AR19: 0 | AS19: 0 | AT19: 0 | AU19: 0 | AV19: 0 | AW19: 0 | AX19: 0 | AY19: 0 | AZ19: 0 | BA19: 0 | BB19: 0 | BC19: 0 | BD19: 0 | BE19: 0 | BF19: 0 | BG19: 0 | BH19: 0 | BI19: 0 | BJ19: 0 | BK19: 0 | BL19: 0 | BM19: 0 | BN19: 0 | BO19: 0 | BP19: 0 | BQ19: 0 | BR19: 0 | BS19: 0 | BT19: 0 | BU19: 0 | BV19: 0 | BW19: 0 | BX19: 0 | BY19: 0 | CK19: 0 | CO19: =BG19-AP19 -> 0 | CP19: =IF(AP19<>0,CO19/AP19,"") | CQ19: =AP19/D19 -> #DIV/0! | CR19: =BG19/AP19 -> #DIV/0!
A20: =IF((E20+V20)<>0, "in", "ẩn") -> in | C20: +Doanh thu phí chuyển nhượng condotel | D20: 70000000 | E20: 0 | F20: 0 | K20: 20000000 | L20: 20000000 | P20: 10000000 | Q20: 20000000 | R20: 0 | S20: 20000000 | T20: 20000000 | U20: 30000000 | V20: 80000000 | W20: 80000000 | X20: 0 | Y20: 0 | Z20: 40000000 | AA20: 0 | AB20: 0 | AC20: 10000000 | AD20: 0 | AE20: 0 | AF20: 20000000 | AG20: 0 | AH20: 0 | AI20: 10000000 | AK20: 40000000 | AL20: 10000000 | AM20: 20000000 | AN20: 10000000 | AO20: 1.1428571 | AP20: 280000000 | AQ20: 0 | AR20: 0 | AS20: 40000000 | AT20: 40000000 | AU20: 30000000 | AV20: 90000000 | AW20: 20000000 | AX20: 20000000 | AY20: 20000000 | AZ20: 10000000 | BA20: 0 | BB20: 10000000 | BC20: 40000000 | BD20: 160000000 | BE20: 60000000 | BF20: 20000000 | BG20: 200000000 | BH20: 10000000 | BI20: 10000000 | BJ20: 20000000 | BK20: 20000000 | BL20: 10000000 | BM20: 30000000 | BN20: 30000000 | BO20: 20000000 | BP20: 20000000 | BQ20: 10000000 | BR20: 10000000 | BS20: 10000000 | BT20: 40000000 | BU20: 60000000 | BV20: 70000000 | BW20: 30000000 | BX20: 0 | BY20: 0 | CK20: 0 | CO20: =BG20-AP20 -> -80000000 | CP20: =IF(AP20<>0,CO20/AP20,"") -> -0.28571429 | CQ20: =AP20/D20 -> 4 | CR20: =BG20/AP20 -> 0.71428571
A21: =IF((E21+V21)<>0, "in", "ẩn") -> in | C21: + Doanh thu tímeshare | D21: 57907224 | E21: 0 | F21: 0 | G21: 0 | H21: 0 | I21: 0 | J21: 0 | K21: 13227272 | L21: 0 | M21: 0 | N21: 17814772 | O21: 0 | P21: 0 | Q21: 26865180 | R21: 0 | S21: 13227272 | T21: 17814772 | U21: 26865180 | V21: 1.422096e+08 | W21: 1.422096e+08 | X21: 0 | Y21: 0 | Z21: 56882464 | AA21: 0 | AB21: 0 | AC21: 31897453 | AD21: 0 | AE21: 0 | AF21: 23843045 | AG21: 0 | AH21: 0 | AI21: 29586634 | AK21: 56882464 | AL21: 31897453 | AM21: 23843045 | AN21: 29586634 | AO21: 2.4558179 | AP21: 333915665 | AQ21: 0 | AR21: 0 | AS21: 56882464 | AT21: 0 | AU21: 0 | AV21: 91015513 | AW21: 0 | AX21: 0 | AY21: 94196206 | AZ21: 0 | BA21: 0 | BB21: 91821482 | BC21: 56882464 | BD21: 91015513 | BE21: 94196206 | BF21: 91821482 | BG21: 348586726 | BH21: 0 | BI21: 0 | BJ21: 62570710 | BK21: 0 | BL21: 0 | BM21: 100117064 | BN21: 0 | BO21: 0 | BP21: 89486396 | BQ21: 0 | BR21: 0 | BS21: 96412556 | BT21: 62570710 | BU21: 100117064 | BV21: 89486396 | BW21: 96412556 | BX21: 0 | BY21: 0 | CK21: 0 | CO21: =BG21-AP21 -> 14671061 | CP21: =IF(AP21<>0,CO21/AP21,"") -> 0.043936426 | CQ21: =AP21/D21 -> 5.7663905 | CR21: =BG21/AP21 -> 1.0439364
A22: =IF((E22+V22)<>0, "in", "ẩn") -> in | C22: - Doanh thu HĐ khác (thu hộ, chi hộ tổng kết) | D22: 310138889 | E22: 0 | I22: 0 | J22: 0 | K22: 0 | L22: 0 | M22: 0 | N22: 0 | O22: 0 | P22: 0 | Q22: 310138889 | R22: 0 | S22: 0 | T22: 0 | U22: 310138889 | V22: 84922038 | W22: 84922038 | X22: 84922038 | Y22: 0 | Z22: 0 | AA22: 0 | AB22: 0 | AC22: 0 | AD22: 0 | AE22: 0 | AF22: 0 | AG22: 0 | AH22: 0 | AI22: 0 | AK22: 84922038 | AL22: 0 | AM22: 0 | AN22: 0 | AO22: 0.27381938 | AP22: 969470373 | AQ22: 84922038 | AR22: 0 | AS22: 0 | AT22: 0 | AU22: 0 | AV22: 0 | AW22: 0 | AX22: 0 | AY22: 0 | AZ22: 0 | BA22: 11115000 | BB22: 873433335 | BC22: 84922038 | BD22: 0 | BE22: 0 | BF22: 884548335 | BG22: 0 | BH22: 0 | BI22: 0 | BJ22: 0 | BK22: 0 | BL22: 0 | BM22: 0 | BN22: 0 | BO22: 0 | BP22: 0 | BQ22: 0 | BR22: 0 | BS22: 0 | BT22: 0 | BU22: 0 | BV22: 0 | BW22: 0 | BX22: 0 | BY22: 0 | CK22: 0 | CO22: =BG22-AP22 -> -969470373 | CP22: =IF(AP22<>0,CO22/AP22,"") -> -1 | CQ22: =AP22/D22 -> 3.1259233 | CR22: =BG22/AP22 -> 0
A23: =IF((E23+V23)<>0, "in", "ẩn") -> ẩn | C23: 2. Các khoản giảm trừ doanh thu | D23: 2391574 | E23: 0 | F23: 0 | G23: 0 | H23: 0 | I23: 0 | J23: 0 | K23: 0 | L23: 0 | M23: 0 | N23: 0 | O23: 2391574 | P23: 0 | Q23: 0 | R23: 0 | S23: 0 | T23: 0 | U23: 2391574 | V23: 0 | W23: 0 | X23: 0 | Y23: 0 | Z23: 0 | AA23: 0 | AB23: 0 | AC23: 0 | AD23: 0 | AE23: 0 | AF23: 0 | AG23: 0 | AH23: 0 | AI23: 0 | AK23: 0 | AL23: 0 | AM23: 0 | AN23: 0 | AO23: 0 | AP23: 2813779 | AQ23: 0 | AR23: 1048000 | AS23: 0 | AT23: 0 | AU23: 1100931 | AV23: 0 | AW23: 0 | AX23: 0 | AY23: 0 | AZ23: 664848 | BA23: 0 | BB23: 0 | BC23: 1048000 | BD23: 1100931 | BE23: 0 | BF23: 664848 | BG23: 0 | BH23: 0 | BI23: 0 | BJ23: 0 | BK23: 0 | BL23: 0 | BM23: 0 | BN23: 0 | BO23: 0 | BP23: 0 | BQ23: 0 | BR23: 0 | BS23: 0 | BT23: 0 | BU23: 0 | BV23: 0 | BW23: 0 | BX23: 0 | BY23: 0 | CK23: 0 | CO23: =BG23-AP23 -> -2813779 | CP23: =IF(AP23<>0,CO23/AP23,"") -> -1 | CQ23: =AP23/D23 -> 1.1765385 | CR23: =BG23/AP23 -> 0
A24: =IF((E24+V24)<>0, "in", "ẩn") -> ẩn | C24: - Chiết khấu thương mại | D24: 0 | E24: 0 | R24: 0 | S24: 0 | T24: 0 | U24: 0 | V24: 0 | W24: 0 | AK24: 0 | AL24: 0 | AM24: 0 | AN24: 0 | AP24: 0 | BC24: 0 | BD24: 0 | BE24: 0 | BF24: 0 | BG24: 0 | BT24: 0 | BU24: 0 | BV24: 0 | BW24: 0 | BX24: 0 | CO24: =BG24-AP24 -> 0 | CP24: =IF(AP24<>0,CO24/AP24,"") | CQ24: =AP24/D24 -> #DIV/0! | CR24: =BG24/AP24 -> #DIV/0!
A25: =IF((E25+V25)<>0, "in", "ẩn") -> ẩn | C25: - Giảm giá hàng bán | D25: 0 | E25: 0 | F25: 0 | G25: 0 | H25: 0 | I25: 0 | J25: 0 | K25: 0 | L25: 0 | M25: 0 | N25: 0 | O25: 0 | P25: 0 | Q25: 0 | R25: 0 | S25: 0 | T25: 0 | U25: 0 | V25: 0 | W25: 0 | X25: 0 | Y25: 0 | Z25: 0 | AA25: 0 | AB25: 0 | AC25: 0 | AD25: 0 | AE25: 0 | AF25: 0 | AG25: 0 | AH25: 0 | AI25: 0 | AK25: 0 | AL25: 0 | AM25: 0 | AN25: 0 | AP25: 1048000 | AQ25: 0 | AR25: 1048000 | AS25: 0 | AT25: 0 | AU25: 0 | AV25: 0 | AW25: 0 | AX25: 0 | AY25: 0 | AZ25: 0 | BA25: 0 | BB25: 0 | BC25: 1048000 | BD25: 0 | BE25: 0 | BF25: 0 | BG25: 0 | BH25: 0 | BI25: 0 | BJ25: 0 | BK25: 0 | BL25: 0 | BM25: 0 | BN25: 0 | BO25: 0 | BP25: 0 | BQ25: 0 | BR25: 0 | BS25: 0 | BT25: 0 | BU25: 0 | BV25: 0 | BW25: 0 | BX25: 0 | BY25: 0 | CK25: 0 | CO25: =BG25-AP25 -> -1048000 | CP25: =IF(AP25<>0,CO25/AP25,"") -> -1 | CQ25: =AP25/D25 -> #DIV/0! | CR25: =BG25/AP25 -> 0
A26: =IF((E26+V26)<>0, "in", "ẩn") -> ẩn | C26: - hàng bán bị trả lại | D26: 2391574 | E26: 0 | F26: 0 | G26: 0 | H26: 0 | I26: 0 | J26: 0 | K26: 0 | L26: 0 | M26: 0 | N26: 0 | O26: 2391574 | P26: 0 | Q26: 0 | R26: 0 | S26: 0 | T26: 0 | U26: 2391574 | V26: 0 | W26: 0 | X26: 0 | Y26: 0 | Z26: 0 | AA26: 0 | AB26: 0 | AC26: 0 | AD26: 0 | AE26: 0 | AF26: 0 | AG26: 0 | AH26: 0 | AI26: 0 | AK26: 0 | AL26: 0 | AM26: 0 | AN26: 0 | AO26: 0 | AP26: 1765779 | AQ26: 0 | AR26: 0 | AS26: 0 | AT26: 0 | AU26: 1100931 | AV26: 0 | AW26: 0 | AX26: 0 | AY26: 0 | AZ26: 664848 | BA26: 0 | BB26: 0 | BC26: 0 | BD26: 1100931 | BE26: 0 | BF26: 664848 | BG26: 0 | BH26: 0 | BI26: 0 | BJ26: 0 | BK26: 0 | BL26: 0 | BM26: 0 | BN26: 0 | BO26: 0 | BP26: 0 | BQ26: 0 | BR26: 0 | BS26: 0 | BT26: 0 | BU26: 0 | BV26: 0 | BW26: 0 | BX26: 0 | BY26: 0 | CK26: 0 | CO26: =BG26-AP26 -> -1765779 | CP26: =IF(AP26<>0,CO26/AP26,"") -> -1 | CQ26: =AP26/D26 -> 0.73833342 | CR26: =BG26/AP26 -> 0
A27: =IF((E27+V27)<>0, "in", "ẩn") -> ẩn | C27: - Thuế tiêu thụ ĐB, Thuế xuất khẩu phải nộp | D27: 0 | E27: 0 | R27: 0 | S27: 0 | T27: 0 | U27: 0 | V27: 0 | W27: 0 | AK27: 0 | AL27: 0 | AM27: 0 | AN27: 0 | AP27: 0 | BC27: 0 | BD27: 0 | BE27: 0 | BF27: 0 | BG27: 0 | BT27: 0 | BU27: 0 | BV27: 0 | BW27: 0 | BX27: 0 | CO27: =BG27-AP27 -> 0 | CP27: =IF(AP27<>0,CO27/AP27,"") | CQ27: =AP27/D27 -> #DIV/0! | CR27: =BG27/AP27 -> #DIV/0!
A28: =IF((E28+V28)<>0, "in", "ẩn") -> in | C28: 3. Doanh thu thuần về bán hàng và cung cấp dịch vụ (10 = 01 - 02) | D28: 251735629906 | E28: 28074834024 | F28: 8625085726 | G28: 3123216088 | H28: 6873593666 | I28: 9452938544 | J28: 12187684327 | K28: 14572553903 | L28: 57110446262 | M28: 81979724061 | N28: 27445755387 | O28: 10023023647 | P28: 8751235578 | Q28: 11590372717 | R28: 18621895480 | S28: 36213176774 | T28: 166535925710 | U28: 30364631942 | V28: 2.8388901e+11 | W28: 2.8388901e+11 | X28: 1.3890605e+10 | Y28: 6.7959294e+09 | Z28: 8.7641859e+09 | AA28: 1.1350535e+10 | AB28: 1.2053007e+10 | AC28: 1.1460245e+10 | AD28: 5.7113188e+10 | AE28: 7.8874245e+10 | AF28: 5.4010531e+10 | AG28: 1.0638425e+10 | AH28: 9.1471312e+09 | AI28: 9.7909863e+09 | AK28: 2.945072e+10 | AL28: 3.4863787e+10 | AM28: 1.8999796e+11 | AN28: 2.9576543e+10 | AO28: 1.1277268 | AP28: 290849364419 | AQ28: 13797963587 | AR28: 6658826230 | AS28: 9019405457 | AT28: 11016654074 | AU28: 11809085391 | AV28: 10390531914 | AW28: 41024125459 | AX28: 73871522687 | AY28: 80278102476 | AZ28: 11306164799 | BA28: 8531991581 | BB28: 13144990764 | BC28: 29476195274 | BD28: 33216271379 | BE28: 195173750622 | BF28: 32983147144 | BG28: 303818820953 | BH28: 7430996486 | BI28: 8583276880 | BJ28: 10174546674 | BK28: 12180080870 | BL28: 11934279308 | BM28: 12940754388 | BN28: 49533062151 | BO28: 84816242627 | BP28: 72959961527 | BQ28: 12101915370 | BR28: 8966700330 | BS28: 12197004342 | BT28: 26188820040 | BU28: 37055114566 | BV28: 207309266305 | BW28: 33265620042 | BX28: 8054506984 | BY28: 8054506984 | CK28: 8054506984 | CO28: =BG28-AP28 -> 12969456534 | CP28: =IF(AP28<>0,CO28/AP28,"") -> 0.044591662 | CQ28: =AP28/D28 -> 1.1553762 | CR28: =BG28/AP28 -> 1.0445917
A29: =IF((E29+V29)<>0, "in", "ẩn") -> in | C29: 4. Giá vốn hàng bán | D29: 231346666296 | E29: 25422073947 | F29: 7805180024 | G29: 2838392433 | H29: 6199087938 | I29: 8579413552 | J29: 11070737060 | K29: 13271538977 | L29: 52763714267 | M29: 76245376692 | N29: 25361766850 | O29: 9048980524 | P29: 7907134663 | Q29: 10255343316 | R29: 16842660395 | S29: 32921689589 | T29: 154370857809 | U29: 27211458503 | V29: 2.6122328e+11 | W29: 2.6122328e+11 | X29: 1.181808e+10 | Y29: 6.1402081e+09 | Z29: 7.8953471e+09 | AA29: 1.042509e+10 | AB29: 1.1081049e+10 | AC29: 1.0498437e+10 | AD29: 5.2959891e+10 | AE29: 7.329279e+10 | AF29: 5.0217994e+10 | AG29: 9.7252763e+09 | AH29: 8.3326551e+09 | AI29: 8.8364592e+09 | AK29: 2.5853635e+10 | AL29: 3.2004575e+10 | AM29: 1.7647067e+11 | AN29: 2.6894391e+10 | AO29: 1.1291422 | AP29: 267099534221 | AQ29: 11723079196 | AR29: 6027309576 | AS29: 8115781155 | AT29: 10067966819 | AU29: 10787121764 | AV29: 9327814791 | AW29: 37875065022 | AX29: 68586055201 | AY29: 74638812097 | AZ29: 10272549090 | BA29: 7756915117 | BB29: 11921064393 | BC29: 25866169927 | BD29: 30182903374 | BE29: 181099932320 | BF29: 29950528600 | BG29: 280015516319 | BH29: 6755081961 | BI29: 7793153910 | BJ29: 9188732975 | BK29: 11131877837 | BL29: 10915233570 | BM29: 11732965898 | BN29: 45778470589 | BO29: 78766092027 | BP29: 67791910047 | BQ29: 11016993095 | BR29: 8161586611 | BS29: 10983417799 | BT29: 23736968846 | BU29: 33780077305 | BV29: 192336472663 | BW29: 30161997505 | BX29: 7325483177 | BY29: 7325483177 | CK29: 7325483177 | CO29: =BG29-AP29 -> 12915982098 | CP29: =IF(AP29<>0,CO29/AP29,"") -> 0.048356438 | CQ29: =AP29/D29 -> 1.1545424 | CR29: =BG29/AP29 -> 1.0483564
A30: =IF((E30+V30)<>0, "in", "ẩn") -> in | C30: - GV mua hàng để bán hàng cho Givral | D30: 68316845843 | E30: 15579102828 | F30: 5420218210 | G30: 1416906756 | H30: 4347889639 | I30: 4394088223 | J30: 5107226643 | K30: 5027790863 | L30: 5763730719 | M30: 10219811699 | N30: 6420416282 | O30: 6795766086 | P30: 5554039682 | Q30: 7848961041 | R30: 11185014605 | S30: 14529105729 | T30: 22403958700 | U30: 20198766809 | V30: 7.3039102e+10 | W30: 7.3039102e+10 | X30: 4.4248993e+09 | Y30: 4.3578553e+09 | Z30: 5.4976021e+09 | AA30: 5.3635143e+09 | AB30: 5.3635143e+09 | AC30: 5.0282946e+09 | AD30: 5.627812e+09 | AE30: 1.0372419e+10 | AF30: 8.0968033e+09 | AG30: 6.0339535e+09 | AH30: 5.6987339e+09 | AI30: 7.1737003e+09 | AK30: 1.4280357e+10 | AL30: 1.5755323e+10 | AM30: 2.4097034e+10 | AN30: 1.8906388e+10 | AO30: 1.0691229 | AP30: 73476365552 | AQ30: 4333616469 | AR30: 4241238614 | AS30: 6391646649 | AT30: 4881923313 | AU30: 5436790975 | AV30: 4340558601 | AW30: 5575131561 | AX30: 8264495546 | AY30: 7169507126 | AZ30: 7755543597 | BA30: 6002542391 | BB30: 9083370710 | BC30: 14966501732 | BD30: 14659272889 | BE30: 21009134233 | BF30: 22841456698 | BG30: 75638268099 | BH30: 5063870958 | BI30: 2422492564 | BJ30: 6510691233 | BK30: 5063870958 | BL30: 5282756790 | BM30: 5063870958 | BN30: 6840416674 | BO30: 9123472526 | BP30: 8816783484 | BQ30: 7234101369 | BR30: 5535018942 | BS30: 8680921643 | BT30: 13997054755 | BU30: 15410498706 | BV30: 24780672684 | BW30: 21450041954 | BX30: 5634272173 | BY30: 5634272173 | CK30: 5634272173 | CO30: =BG30-AP30 -> 2161902547 | CP30: =IF(AP30<>0,CO30/AP30,"") -> 0.029423101 | CQ30: =AP30/D30 -> 1.0755234 | CR30: =BG30/AP30 -> 1.0294231
A31: =IF((E31+V31)<>0, "in", "ẩn") -> in | C31: + GV - Givral - Daily | D31: 62963585843 | E31: 15579102828 | F31: 5420218210 | G31: 1416906756 | H31: 4347889639 | I31: 4394088223 | J31: 5107226643 | K31: 4662480863 | L31: 5575750719 | M31: 6602741699 | N31: 5237516282 | O31: 6795766086 | P31: 5554039682 | Q31: 7848961041 | R31: 11185014605 | S31: 14163795729 | T31: 17416008700 | U31: 20198766809 | V31: 6.7043928e+10 | W31: 6.7043928e+10 | X31: 4.4248993e+09 | Y31: 4.3578553e+09 | Z31: 5.4976021e+09 | AA31: 5.3635143e+09 | AB31: 5.3635143e+09 | AC31: 5.0282946e+09 | AD31: 5.0282946e+09 | AE31: 7.3748321e+09 | AF31: 5.6987339e+09 | AG31: 6.0339535e+09 | AH31: 5.6987339e+09 | AI31: 7.1737003e+09 | AK31: 1.4280357e+10 | AL31: 1.5755323e+10 | AM31: 1.8101861e+10 | AN31: 1.8906388e+10 | AO31: 1.0648048 | AP31: 70279141552 | AQ31: 4333616469 | AR31: 4241238614 | AS31: 6391646649 | AT31: 4881923313 | AU31: 5436790975 | AV31: 4340558601 | AW31: 5270931561 | AX31: 7088480546 | AY31: 5452498126 | AZ31: 7755543597 | BA31: 6002542391 | BB31: 9083370710 | BC31: 14966501732 | BD31: 14659272889 | BE31: 17811910233 | BF31: 22841456698 | BG31: 72341013692 | BH31: 5063870958 | BI31: 2422492564 | BJ31: 6510691233 | BK31: 5063870958 | BL31: 5282756790 | BM31: 5063870958 | BN31: 6510691233 | BO31: 7738625675 | BP31: 7234101369 | BQ31: 7234101369 | BR31: 5535018942 | BS31: 8680921643 | BT31: 13997054755 | BU31: 15410498706 | BV31: 21483418277 | BW31: 21450041954 | BX31: 5634272173 | BY31: 5634272173 | CK31: 5634272173 | CO31: =BG31-AP31 -> 2061872140 | CP31: =IF(AP31<>0,CO31/AP31,"") -> 0.029338323 | CQ31: =AP31/D31 -> 1.1161871 | CR31: =BG31/AP31 -> 1.0293383
A32: =IF((E32+V32)<>0, "in", "ẩn") -> in | C32: + GV - Givral - Trung thu | D32: 5353260000 | E32: 0 | F32: 0 | G32: 0 | H32: 0 | I32: 0 | J32: 0 | K32: 365310000 | L32: 1.8798e+08 | M32: 3617070000 | N32: 1182900000 | O32: 0 | P32: 0 | Q32: 0 | R32: 0 | S32: 365310000 | T32: 4987950000 | U32: 0 | V32: 5.9951735e+09 | W32: 5.9951735e+09 | X32: 0 | Y32: 0 | Z32: 0 | AA32: 0 | AB32: 0 | AC32: 0 | AD32: 5.9951735e+08 | AE32: 2.9975867e+09 | AF32: 2.3980694e+09 | AG32: 0 | AH32: 0 | AI32: 0 | AK32: 0 | AL32: 0 | AM32: 5.9951735e+09 | AN32: 0 | AO32: 1.1199108 | AP32: 3197224000 | AW32: 304200000 | AX32: 1176015000 | AY32: 1717009000 | BC32: 0 | BD32: 0 | BE32: 3197224000 | BF32: 0 | BG32: 3297254407 | BH32: 0 | BI32: 0 | BJ32: 0 | BK32: 0 | BL32: 0 | BM32: 0 | BN32: 329725441 | BO32: 1384846851 | BP32: 1582682115 | BQ32: 0 | BR32: 0 | BS32: 0 | BT32: 0 | BU32: 0 | BV32: 3297254407 | BW32: 0 | BX32: 0 | CO32: =BG32-AP32 -> 100030407 | CP32: =IF(AP32<>0,CO32/AP32,"") -> 0.031286643 | CQ32: =AP32/D32 -> 0.59724803 | CR32: =BG32/AP32 -> 1.0312866
A33: =IF((E33+V33)<>0, "in", "ẩn") -> in | C33: - GV mua hàng để bán hàng cho KTT | D33: 162124694873 | E33: 9842971119 | F33: 2384961814 | G33: 1421485677 | H33: 1851198299 | I33: 4185325329 | J33: 5962494816 | K33: 8241124478 | L33: 46997359912 | M33: 66022941357 | N33: 18938726932 | O33: 2249496256 | P33: 2349376799 | Q33: 1520203204 | R33: 5657645790 | S33: 18388944623 | T33: 131959028201 | U33: 6119076259 | V33: 1.8276904e+11 | W33: 1.8276904e+11 | X33: 2182543104 | Y33: 1615042488 | Z33: 2.3940268e+09 | AA33: 5.0578572e+09 | AB33: 5.7138163e+09 | AC33: 5.4664238e+09 | AD33: 4.7328361e+10 | AE33: 6.2916653e+10 | AF33: 4.2117472e+10 | AG33: 3.6876046e+09 | AH33: 2.6302031e+09 | AI33: 1.6590407e+09 | AK33: 6.1916124e+09 | AL33: 1.6238097e+10 | AM33: 1.5236249e+11 | AN33: 7.9768483e+09 | AO33: 1.1273362 | AP33: 187311821217 | AQ33: 2182543104 | AR33: 1615042488 | AS33: 1720416324 | AT33: 5182325324 | AU33: 5346612607 | AV33: 4983538008 | AW33: 32296215279 | AX33: 60317841473 | AY33: 67462076789 | AZ33: 2509777311 | BA33: 1736029544 | BB33: 1959402966 | BC33: 5518001916 | BD33: 15512475939 | BE33: 160076133541 | BF33: 6205209821 | BG33: 200712789719 | BH33: 1683982821 | BI33: 1785712847 | BJ33: 2670813560 | BK33: 6060778697 | BL33: 5625248598 | BM33: 6661866758 | BN33: 38930825733 | BO33: 69635391319 | BP33: 58967898381 | BQ33: 3775663544 | BR33: 2619339487 | BS33: 2295267974 | BT33: 6140509228 | BU33: 18347894053 | BV33: 167534115433 | BW33: 8690271005 | BX33: 1683982822 | BY33: 1683982822 | CK33: 1683982822 | CO33: =BG33-AP33 -> 13400968502 | CP33: =IF(AP33<>0,CO33/AP33,"") -> 0.071543635 | CQ33: =AP33/D33 -> 1.1553565 | CR33: =BG33/AP33 -> 1.0715436
A34: =IF((E34+V34)<>0, "in", "ẩn") -> in | C34: + GV - KTT - Daily | D34: 38429827473 | E34: 9842971119 | F34: 2384961814 | G34: 1421485677 | H34: 1851198299 | I34: 4185325329 | J34: 5962494816 | K34: 3734074678 | L34: 6173012712 | M34: 4095632227 | N34: 2502567662 | O34: 2249496256 | P34: 2349376799 | Q34: 1520201204 | R34: 5657645790 | S34: 13881894823 | T34: 12771212601 | U34: 6119074259 | V34: 4.4842176e+10 | W34: 4.4842176e+10 | X34: 2182543104 | Y34: 1615042488 | Z34: 2.3940268e+09 | AA34: 5.0578572e+09 | AB34: 5.7138163e+09 | AC34: 5.4664238e+09 | AD34: 6.3397446e+09 | AE34: 4.9094795e+09 | AF34: 3.1863939e+09 | AG34: 3.6876046e+09 | AH34: 2.6302031e+09 | AI34: 1.6590407e+09 | AK34: 6.1916124e+09 | AL34: 1.6238097e+10 | AM34: 1.4435618e+10 | AN34: 7.9768483e+09 | AO34: 1.1668586 | AP34: 41614188377 | AQ34: 2182543104 | AR34: 1615042488 | AS34: 1720416324 | AT34: 5182325324 | AU34: 5346612607 | AV34: 4983538008 | AW34: 4920500399 | AX34: 5367856213 | AY34: 4099418489 | AZ34: 2500502911 | BA34: 1736029544 | BB34: 1959402966 | BC34: 5518001916 | BD34: 15512475939 | BE34: 14387775101 | BF34: 6195935421 | BG34: 51370227920 | BH34: 1683982821 | BI34: 1785712847 | BJ34: 2670813560 | BK34: 6060778697 | BL34: 5625248598 | BM34: 6661866758 | BN34: 6460980595 | BO34: 6911515363 | BP34: 4819057676 | BQ34: 3775663544 | BR34: 2619339487 | BS34: 2295267974 | BT34: 6140509228 | BU34: 18347894053 | BV34: 18191553634 | BW34: 8690271005 | BX34: 1683982822 | BY34: 1683982822 | CK34: 1683982822 | CO34: =BG34-AP34 -> 9756039543 | CP34: =IF(AP34<>0,CO34/AP34,"") -> 0.23444022 | CQ34: =AP34/D34 -> 1.0828617 | CR34: =BG34/AP34 -> 1.2344402
A35: =IF((E35+V35)<>0, "in", "ẩn") -> in | C35: + GV - KTT - Trung thu | D35: 123694865400 | E35: 0 | F35: 0 | G35: 0 | H35: 0 | I35: 0 | J35: 0 | K35: 4507049800 | L35: 40824347200 | M35: 61927309130 | N35: 16436159270 | O35: 0 | P35: 0 | Q35: 0 | R35: 0 | S35: 4507049800 | T35: 119187815600 | U35: 0 | V35: 1.3792687e+11 | W35: 1.3792687e+11 | X35: 0 | Y35: 0 | Z35: 0 | AA35: 0 | AB35: 0 | AC35: 0 | AD35: 4.0988616e+10 | AE35: 5.8007173e+10 | AF35: 3.8931078e+10 | AG35: 0 | AH35: 0 | AI35: 0 | AK35: 0 | AL35: 0 | AM35: 1.3792687e+11 | AN35: 0 | AO35: 1.1150573 | AP35: 145697632840 | AW35: 27375714880 | AX35: 54949985260 | AY35: 63362658300 | AZ35: 9274400 | BC35: 0 | BD35: 0 | BE35: 145688358440 | BF35: 9274400 | BG35: 149342561799 | BH35: 0 | BI35: 0 | BJ35: 0 | BK35: 0 | BL35: 0 | BM35: 0 | BN35: 32469845138 | BO35: 62723875956 | BP35: 54148840705 | BQ35: 0 | BR35: 0 | BS35: 0 | BT35: 0 | BU35: 0 | BV35: 149342561799 | BW35: 0 | BX35: 0 | CO35: =BG35-AP35 -> 3644928959 | CP35: =IF(AP35<>0,CO35/AP35,"") -> 0.025017077 | CQ35: =AP35/D35 -> 1.1778794 | CR35: =BG35/AP35 -> 1.0250171
A36: =IF((E36+V36)<>0, "in", "ẩn") -> in | C36: - GV hoạt động thương mại khác | D36: 572322000 | E36: 0 | F36: 0 | G36: 0 | H36: 0 | I36: 0 | J36: 0 | K36: 0 | L36: 0 | M36: 0 | N36: 0 | O36: 0 | P36: 0 | Q36: 572322000 | R36: 0 | S36: 0 | T36: 0 | U36: 572322000 | V36: 5285589695 | W36: 5285589695 | X36: 5121997585 | Y36: 163592110 | Z36: 0 | AA36: 0 | AB36: 0 | AC36: 0 | AD36: 0 | AE36: 0 | AF36: 0 | AG36: 0 | AH36: 0 | AI36: 0 | AK36: 5285589695 | AL36: 0 | AM36: 0 | AN36: 0 | AO36: 9.2353425 | AP36: 5285589695 | AQ36: 5121997585 | AR36: 163592110 | AS36: 0 | AT36: 0 | AU36: 0 | AV36: 0 | AW36: 0 | AX36: 0 | AY36: 0 | AZ36: 0 | BA36: 0 | BB36: 0 | BC36: 5285589695 | BD36: 0 | BE36: 0 | BF36: 0 | BG36: 3577720317 | BH36: 0 | BI36: 3577720317 | BJ36: 0 | BK36: 0 | BL36: 0 | BM36: 0 | BN36: 0 | BO36: 0 | BP36: 0 | BQ36: 0 | BR36: 0 | BS36: 0 | BT36: 3577720317 | BU36: 0 | BV36: 0 | BW36: 0 | BX36: 0 | BY36: 0 | CK36: 0 | CO36: =BG36-AP36 -> -1707869378 | CP36: =IF(AP36<>0,CO36/AP36,"") -> -0.32311804 | CQ36: =AP36/D36 -> 9.2353425 | CR36: =BG36/AP36 -> 0.67688196
A37: =IF((E37+V37)<>0, "in", "ẩn") -> in | C37: + GV Bánh chưng truyền thống cho Kem TT | D37: 572322000 | E37: 0 | F37: 0 | G37: 0 | H37: 0 | I37: 0 | J37: 0 | K37: 0 | L37: 0 | M37: 0 | N37: 0 | O37: 0 | P37: 0 | Q37: 572322000 | R37: 0 | S37: 0 | T37: 0 | U37: 572322000 | V37: 2238550000 | W37: 2238550000 | X37: 2098069000 | Y37: 140481000 | Z37: 0 | AA37: 0 | AB37: 0 | AC37: 0 | AD37: 0 | AE37: 0 | AF37: 0 | AG37: 0 | AH37: 0 | AI37: 0 | AK37: 2238550000 | AL37: 0 | AM37: 0 | AN37: 0 | AO37: 3.9113471 | AP37: 2238550000 | AQ37: 2098069000 | AR37: 140481000 | BC37: 2238550000 | BD37: 0 | BE37: 0 | BF37: 0 | BG37: 0 | BT37: 0 | BU37: 0 | BV37: 0 | BW37: 0 | BX37: 0 | BY37: 0 | CK37: 0 | CO37: =BG37-AP37 -> -2238550000 | CP37: =IF(AP37<>0,CO37/AP37,"") -> -1 | CQ37: =AP37/D37 -> 3.9113471 | CR37: =BG37/AP37 -> 0
A38: =IF((E38+V38)<>0, "in", "ẩn") -> in | C38: + GV Hộp quà tết cho vietinbank và khách lẻ | D38: 0 | E38: 0 | F38: 0 | G38: 0 | H38: 0 | I38: 0 | J38: 0 | K38: 0 | L38: 0 | M38: 0 | N38: 0 | O38: 0 | P38: 0 | Q38: 0 | R38: 0 | S38: 0 | T38: 0 | U38: 0 | V38: 3047039695 | W38: 3047039695 | X38: 3023928585 | Y38: 23111110 | Z38: 0 | AA38: 0 | AB38: 0 | AC38: 0 | AD38: 0 | AE38: 0 | AF38: 0 | AG38: 0 | AH38: 0 | AI38: 0 | AK38: 3047039695 | AL38: 0 | AM38: 0 | AN38: 0 | AP38: 3047039695 | AQ38: 3023928585 | AR38: 23111110 | BC38: 3047039695 | BD38: 0 | BE38: 0 | BF38: 0 | BG38: 3577720317 | BH38: 0 | BI38: 3577720317 | BJ38: 0 | BK38: 0 | BL38: 0 | BM38: 0 | BN38: 0 | BO38: 0 | BP38: 0 | BQ38: 0 | BR38: 0 | BS38: 0 | BT38: 3577720317 | BU38: 0 | BV38: 0 | BW38: 0 | BX38: 0 | BY38: 0 | CK38: 0 | CO38: =BG38-AP38 -> 530680622 | CP38: =IF(AP38<>0,CO38/AP38,"") -> 0.17416269 | CQ38: =AP38/D38 -> #DIV/0! | CR38: =BG38/AP38 -> 1.1741627
A39: =IF((E39+V39)<>0, "in", "ẩn") -> in | C39: - Giá vốn liên quan đến condotel | D39: 22664691 | E39: 0 | F39: 0 | G39: 0 | H39: 0 | I39: 0 | J39: 1015601 | K39: 2623636 | L39: 2623636 | M39: 2623636 | N39: 2623636 | O39: 3718182 | P39: 3718182 | Q39: 3718182 | R39: 0 | S39: 3639237 | T39: 7870908 | U39: 11154546 | V39: 44618184 | W39: 44618184 | X39: 3718182 | Y39: 3718182 | Z39: 3718182 | AA39: 3718182 | AB39: 3718182 | AC39: 3718182 | AD39: 3718182 | AE39: 3718182 | AF39: 3718182 | AG39: 3718182 | AH39: 3718182 | AI39: 3718182 | AK39: 11154546 | AL39: 11154546 | AM39: 11154546 | AN39: 11154546 | AO39: 1.9686209 | AP39: 58658184 | AQ39: 0 | AR39: 7436364 | AS39: 3718182 | AT39: 3718182 | AU39: 3718182 | AV39: 3718182 | AW39: 3718182 | AX39: 3718182 | AY39: 7228182 | AZ39: 7228182 | BA39: 7228182 | BB39: 7228182 | BC39: 11154546 | BD39: 11154546 | BE39: 14664546 | BF39: 21684546 | BG39: 86738184 | BH39: 7228182 | BI39: 7228182 | BJ39: 7228182 | BK39: 7228182 | BL39: 7228182 | BM39: 7228182 | BN39: 7228182 | BO39: 7228182 | BP39: 7228182 | BQ39: 7228182 | BR39: 7228182 | BS39: 7228182 | BT39: 21684546 | BU39: 21684546 | BV39: 21684546 | BW39: 21684546 | BX39: 7228182 | BY39: 7228182 | CK39: 7228182 | CO39: =BG39-AP39 -> 28080000 | CP39: =IF(AP39<>0,CO39/AP39,"") -> 0.47870558 | CQ39: =AP39/D39 -> 2.5880866 | CR39: =BG39/AP39 -> 1.4787056
A40: =IF((E40+V40)<>0, "in", "ẩn") -> ẩn | C40: + GV chuyển nhượng condotel | D40: 0 | E40: 0 | F40: 0 | G40: 0 | H40: 0 | I40: 0 | J40: 0 | K40: 0 | L40: 0 | M40: 0 | N40: 0 | O40: 0 | P40: 0 | Q40: 0 | R40: 0 | S40: 0 | T40: 0 | U40: 0 | V40: 0 | W40: 0 | X40: 0 | Y40: 0 | Z40: 0 | AA40: 0 | AB40: 0 | AC40: 0 | AD40: 0 | AE40: 0 | AF40: 0 | AG40: 0 | AH40: 0 | AI40: 0 | AK40: 0 | AL40: 0 | AM40: 0 | AN40: 0 | AP40: 0 | AQ40: 0 | AR40: 0 | AS40: 0 | AT40: 0 | AU40: 0 | AV40: 0 | AW40: 0 | AX40: 0 | AY40: 0 | AZ40: 0 | BA40: 0 | BB40: 0 | BC40: 0 | BD40: 0 | BE40: 0 | BF40: 0 | BG40: 0 | BH40: 0 | BI40: 0 | BJ40: 0 | BK40: 0 | BL40: 0 | BM40: 0 | BN40: 0 | BO40: 0 | BP40: 0 | BQ40: 0 | BR40: 0 | BS40: 0 | BT40: 0 | BU40: 0 | BV40: 0 | BW40: 0 | BX40: 0 | BY40: 0 | CK40: 0 | CO40: =BG40-AP40 -> 0 | CP40: =IF(AP40<>0,CO40/AP40,"") | CQ40: =AP40/D40 -> #DIV/0! | CR40: =BG40/AP40 -> #DIV/0!
A41: =IF((E41+V41)<>0, "in", "ẩn") -> in | C41: + Giá vốn phí quản lý/ bảo trì condotel | D41: 22664691 | E41: 0 | F41: 0 | G41: 0 | H41: 0 | I41: 0 | J41: 1015601 | K41: 2623636 | L41: 2623636 | M41: 2623636 | N41: 2623636 | O41: 3718182 | P41: 3718182 | Q41: 3718182 | R41: 0 | S41: 3639237 | T41: 7870908 | U41: 11154546 | V41: 44618184 | W41: 44618184 | X41: 3718182 | Y41: 3718182 | Z41: 3718182 | AA41: 3718182 | AB41: 3718182 | AC41: 3718182 | AD41: 3718182 | AE41: 3718182 | AF41: 3718182 | AG41: 3718182 | AH41: 3718182 | AI41: 3718182 | AK41: 11154546 | AL41: 11154546 | AM41: 11154546 | AN41: 11154546 | AO41: 1.9686209 | AP41: 58658184 | AQ41: 0 | AR41: 7436364 | AS41: 3718182 | AT41: 3718182 | AU41: 3718182 | AV41: 3718182 | AW41: 3718182 | AX41: 3718182 | AY41: 7228182 | AZ41: 7228182 | BA41: 7228182 | BB41: 7228182 | BC41: 11154546 | BD41: 11154546 | BE41: 14664546 | BF41: 21684546 | BG41: 86738184 | BH41: 7228182 | BI41: 7228182 | BJ41: 7228182 | BK41: 7228182 | BL41: 7228182 | BM41: 7228182 | BN41: 7228182 | BO41: 7228182 | BP41: 7228182 | BQ41: 7228182 | BR41: 7228182 | BS41: 7228182 | BT41: 21684546 | BU41: 21684546 | BV41: 21684546 | BW41: 21684546 | BX41: 7228182 | BY41: 7228182 | CK41: 7228182 | CO41: =BG41-AP41 -> 28080000 | CP41: =IF(AP41<>0,CO41/AP41,"") -> 0.47870558 | CQ41: =AP41/D41 -> 2.5880866 | CR41: =BG41/AP41 -> 1.4787056
A42: =IF((E42+V42)<>0, "in", "ẩn") -> in | C42: - GV HĐ khác | D42: 310138889 | E42: 0 | H42: 0 | I42: 0 | J42: 0 | K42: 0 | L42: 0 | M42: 0 | N42: 0 | O42: 0 | P42: 0 | Q42: 310138889 | R42: 0 | S42: 0 | T42: 0 | U42: 310138889 | V42: 84922038 | W42: 84922038 | X42: 84922038 | Y42: 0 | Z42: 0 | AA42: 0 | AB42: 0 | AC42: 0 | AD42: 0 | AE42: 0 | AF42: 0 | AG42: 0 | AH42: 0 | AI42: 0 | AK42: 84922038 | AL42: 0 | AM42: 0 | AN42: 0 | AO42: 0.27381938 | AP42: 967099573 | AQ42: 84922038 | AR42: 0 | AS42: 0 | AT42: 0 | AU42: 0 | AV42: 0 | AW42: 0 | AX42: 0 | AY42: 0 | AZ42: 0 | BA42: 11115000 | BB42: 871062535 | BC42: 84922038 | BD42: 0 | BE42: 0 | BF42: 882177535 | BG42: 0 | BH42: 0 | BI42: 0 | BJ42: 0 | BK42: 0 | BL42: 0 | BM42: 0 | BN42: 0 | BO42: 0 | BP42: 0 | BQ42: 0 | BR42: 0 | BS42: 0 | BT42: 0 | BU42: 0 | BV42: 0 | BW42: 0 | BX42: 0 | BY42: 0 | CK42: 0 | CO42: =BG42-AP42 -> -967099573 | CP42: =IF(AP42<>0,CO42/AP42,"") -> -1 | CQ42: =AP42/D42 -> 3.118279 | CR42: =BG42/AP42 -> 0
...

Sheet CPQLDN.
F1: THỰC HIỆN NĂM 2025 | T1: KẾ HOẠCH NĂM 2025 | AH1: THỰC HIỆN NĂM 2024 | AV1: THỰC HIỆN NĂM 2026 | BJ1: KẾ HOẠCH NĂM 2026 | BX1: THỰC HIỆN NĂM 2027 | CL1: KẾ HOẠCH NĂM 2027
E2: CP QLDN chi tiết | F2: NĂM 2025 | G2: TH-2025-01 | H2: TH-2025-02 | I2: TH-2025-03 | J2: TH-2025-04 | K2: TH-2025-05 | L2: TH-2025-06 | M2: TH-2025-07 | N2: TH-2025-08 | O2: TH-2025-09 | P2: TH-2025-10 | Q2: TH-2025-11 | R2: TH-2025-12 | T2: NĂM 2025 | U2: KH-2025-01 | V2: KH-2025-02 | W2: KH-2025-03 | X2: KH-2025-04 | Y2: KH-2025-05 | Z2: KH-2025-06 | AA2: KH-2025-07 | AB2: KH-2025-08 | AC2: KH-2025-09 | AD2: KH-2025-10 | AE2: KH-2025-11 | AF2: KH-2025-12 | AH2: NĂM 2024 | AI2: TH-2024-01 | AJ2: TH-2024-02 | AK2: TH-2024-03 | AL2: TH-2024-04 | AM2: TH-2024-05 | AN2: TH-2024-06 | AO2: TH-2024-07 | AP2: TH-2024-08 | AQ2: TH-2024-09 | AR2: TH-2024-10 | AS2: TH-2024-11 | AT2: TH-2024-12 | AV2: NĂM 2026 | AW2: TH-2026-01 | AX2: TH-2026-02 | AY2: TH-2026-03 | AZ2: TH-2026-04 | BA2: TH-2026-05 | BB2: TH-2026-06 | BC2: TH-2026-07 | BD2: TH-2026-08 | BE2: TH-2026-09 | BF2: TH-2026-10 | BG2: TH-2026-11 | BH2: TH-2026-12 | BJ2: NĂM 2026 | BK2: KH-2026-01 | BL2: KH-2026-02 | BM2: KH-2026-03 | BN2: KH-2026-04 | BO2: KH-2026-05 | BP2: KH-2026-06 | BQ2: KH-2026-07 | BR2: KH-2026-08 | BS2: KH-2026-09 | BT2: KH-2026-10 | BU2: KH-2026-11 | BV2: KH-2026-12 | BX2: NĂM 2027 | BY2: TH-2027-01 | BZ2: TH-2027-02 | CA2: TH-2027-03 | CB2: TH-2027-04 | CC2: TH-2027-05 | CD2: TH-2027-06 | CE2: TH-2027-07 | CF2: TH-2027-08 | CG2: TH-2027-09 | CH2: TH-2027-10 | CI2: TH-2027-11 | CJ2: TH-2027-12 | CL2: NĂM 2027 | CM2: KH-2027-01 | CN2: KH-2027-02 | CO2: KH-2027-03 | CP2: KH-2027-04 | CQ2: KH-2027-05 | CR2: KH-2027-06 | CS2: KH-2027-07 | CT2: KH-2027-08 | CU2: KH-2027-09 | CV2: KH-2027-10 | CW2: KH-2027-11 | CX2: KH-2027-12
G3: 1 | H3: 2 | I3: 3 | J3: 4 | K3: 5 | L3: 6 | M3: 7 | N3: 8 | O3: 9 | P3: 10 | Q3: 11 | R3: 12 | AW3: 1 | AX3: 2 | AY3: 3 | AZ3: 4 | BA3: 5 | BB3: 6 | BC3: 7 | BD3: 8 | BE3: 9 | BF3: 10 | BG3: 11 | BH3: 12 | BY3: 1 | BZ3: 2 | CA3: 3 | CB3: 4 | CC3: 5 | CD3: 6 | CE3: 7 | CF3: 8 | CG3: 9 | CH3: 10 | CI3: 11 | CJ3: 12
A4: CT | B4: 9. Chi phí quản lý doanh nghiệp | F4: 20807302319 | G4: 1423642801 | H4: 1255579031 | I4: 1616748999 | J4: 1335684623 | K4: 1195579817 | L4: 2098646855 | M4: 1279490114 | N4: 1281985293 | O4: 1630276362 | P4: 1239794061 | Q4: 4472785982 | R4: 1977088381 | S4: 1162124351 | T4: 2.0191939e+10 | U4: 1.4870743e+09 | V4: 1.4936272e+09 | W4: 1.7748514e+09 | X4: 1.4741734e+09 | Y4: 1.5264682e+09 | Z4: 2.3086992e+09 | AA4: 1.3414477e+09 | AB4: 1.3112221e+09 | AC4: 1.8656646e+09 | AD4: 1.4216221e+09 | AE4: 1.4318813e+09 | AF4: 2.7552077e+09 | AG4: 9938292522 | AH4: 27488502658 | AI4: 2178141707 | AJ4: 2077787709 | AK4: 2344941717 | AL4: 1974387701 | AM4: 2032931184 | AN4: 2494250298 | AO4: 2064843899 | AP4: 2058769462 | AQ4: 1855334066 | AR4: 1388669391 | AS4: 4355412022 | AT4: 2663033502 | AU4: 0 | AV4: 23775488383 | AW4: 1309763830 | AX4: 1432189163 | AY4: 1604975277 | AZ4: 1429038467 | BA4: 2073491748 | BB4: 2973625065 | BC4: 1581382139 | BD4: 1347582139 | BE4: 1627122139 | BF4: 1462165472 | BG4: 4434880472 | BH4: 2499272472 | BJ4: 2.3775488e+10 | BK4: 1309763830 | BL4: 1.4554491e+09 | BM4: 1581715390 | BN4: 1429038467 | BO4: 2073491748 | BP4: 2973625065 | BQ4: 1581382139 | BR4: 1347582139 | BS4: 1627122139 | BT4: 1462165472 | BU4: 4434880472 | BV4: 2499272472
A5: 1+2+3+4+5 | B5: Lương và phúc lơi | F5: 8912691581 | G5: 794942292 | H5: 703470600 | I5: 731395053 | J5: 747176000 | K5: 702180250 | L5: 647241600 | M5: 635611200 | N5: 673241600 | O5: 787223650 | P5: 639327991 | Q5: 625318400 | R5: 1225562945 | S5: 0 | T5: 10175992092 | U5: 783233742 | V5: 695470600 | W5: 740477600 | X5: 842194350 | Y5: 804468350 | Z5: 1063168350 | AA5: 729620350 | AB5: 725320350 | AC5: 798720350 | AD5: 744220350 | AE5: 727320350 | AF5: 1521777350 | AH5: 10666551154 | AI5: 911788650 | AJ5: 958704861 | AK5: 950802765 | AL5: 803831750 | AM5: 765258550 | AN5: 808083850 | AO5: 789059150 | AP5: 815536750 | AQ5: 771099628 | AR5: 893400204 | AS5: 781678946 | AT5: 1417306050 | AU5: 0 | AV5: 9227278614 | AW5: 656209827 | AX5: 681487900 | AY5: 704746287 | AZ5: 710186400 | BA5: 699186400 | BB5: 864686400 | BC5: 699186400 | BD5: 699686400 | BE5: 732686400 | BF5: 706986400 | BG5: 699186400 | BH5: 1373043400 | BJ5: 9.2272786e+09 | BK5: 656209827 | BL5: 7.0474779e+08 | BM5: 681486400 | BN5: 710186400 | BO5: 699186400 | BP5: 864686400 | BQ5: 699186400 | BR5: 699686400 | BS5: 732686400 | BT5: 706986400 | BU5: 699186400 | BV5: 1373043400
B6: Lương và phúc lơi | C6: Chi phí lương hàng tháng, lương tháng 13, thưởng tết | F6: 8262100376 | G6: 704243143 | H6: 664869200 | I6: 687625200 | J6: 709861100 | K6: 664496900 | L6: 614650700 | M6: 601516300 | N6: 640452200 | O6: 591357000 | P6: 598857000 | Q6: 592657000 | R6: 1191514633 | S6: 0 | T6: 9361207543 | U6: 703243143 | V6: 656869200 | W6: 696625200 | X6: 800657000 | Y6: 759557000 | Z6: 762257000 | AA6: 691457000 | AB6: 687157000 | AC6: 738557000 | AD6: 696057000 | AE6: 689157000 | AF6: 1479614000 | AH6: 9996692522 | AI6: 869901800 | AJ6: 849316900 | AK6: 901035100 | AL6: 746341000 | AM6: 725836200 | AN6: 767016500 | AO6: 747116800 | AP6: 778934400 | AQ6: 717325500 | AR6: 842189622 | AS6: 669917500 | AT6: 1381761200 | AU6: 0 | AV6: 8534622927 | AW6: 621738927 | AX6: 624857000 | AY6: 635157000 | AZ6: 672857000 | BA6: 661857000 | BB6: 662357000 | BC6: 661857000 | BD6: 662357000 | BE6: 673357000 | BF6: 664657000 | BG6: 661857000 | BH6: 1331714000 | BJ6: 8534622927 | BK6: 621738927 | BL6: 624857000 | BM6: 635157000 | BN6: 672857000 | BO6: 661857000 | BP6: 662357000 | BQ6: 661857000 | BR6: 662357000 | BS6: 673357000 | BT6: 664657000 | BU6: 661857000 | BV6: 1331714000
A7: 1 | B7: Lương và phúc lơi | D7: Lương theo ngày công | E7: Lương theo ngày công | F7: 7517260043 | G7: 701743143 | H7: 652669200 | I7: 684625200 | J7: 660361100 | K7: 662496900 | L7: 609450700 | M7: 600016300 | N7: 593452200 | O7: 587357000 | P7: 587357000 | Q7: 587357000 | R7: 590374300 | S7: 0 | T7: 8370550543 | U7: 701743143 | V7: 652669200 | W7: 684625200 | X7: 733557000 | Y7: 753557000 | Z7: 752057000 | AA7: 682057000 | AB7: 682057000 | AC7: 682057000 | AD7: 682057000 | AE7: 682057000 | AF7: 682057000 | AG7: Tháng 1 nghỉ 1 nhân sự, Tháng 2 và 3: nhân sự nghỉ sinh đi làm lại, bớt 2 nhân sự HNB và thêm 1 nhân sự khách sạn và chưa gồm lương TGĐ;Tháng 5+6 thêm 1 nhân sự Franchise, phân bổ lương PTGĐ sang OGC 30 tr, chuyển R&D và Franchise sang OCC từ tháng 7/25 | AH7: 9038809622 | AI7: 858901800 | AJ7: 848416900 | AK7: 841935100 | AL7: 693841000 | AM7: 717136200 | AN7: 756616500 | AO7: 743516800 | AP7: 722934400 | AQ7: 712325500 | AR7: 825589622 | AS7: 666317500 | AT7: 651278300 | AU7: 0 | AV7: 7779165927 | AW7: 605238927 | AX7: 620357000 | AY7: 628357000 | AZ7: 658357000 | BA7: 658357000 | BB7: 658357000 | BC7: 658357000 | BD7: 658357000 | BE7: 658357000 | BF7: 658357000 | BG7: 658357000 | BH7: 658357000 | BJ7: 7779165927 | BK7: 605238927 | BL7: 620357000 | BM7: 628357000 | BN7: 658357000 | BO7: 658357000 | BP7: 658357000 | BQ7: 658357000 | BR7: 658357000 | BS7: 658357000 | BT7: 658357000 | BU7: 658357000 | BV7: 658357000
A8: 1 | B8: Lương và phúc lơi | D8: Tháng lương thứ 13 | E8: Tháng lương thứ 13 | F8: 584640333 | G8: 0 | H8: 0 | I8: 0 | J8: 0 | K8: 0 | L8: 0 | M8: 0 | N8: 0 | O8: 0 | P8: 0 | Q8: 0 | R8: 584640333 | S8: 0 | T8: 682057000 | U8: 0 | V8: 0 | W8: 0 | X8: 0 | Y8: 0 | Z8: 0 | AA8: 0 | AB8: 0 | AC8: 0 | AD8: 0 | AE8: 0 | AF8: 682057000 | AH8: 624982900 | AI8: 0 | AJ8: 0 | AK8: 0 | AL8: 0 | AM8: 0 | AN8: 0 | AO8: 0 | AP8: 0 | AQ8: 0 | AR8: 0 | AS8: 0 | AT8: 624982900 | AU8: Chưa bao gồm chi từ quỹ phúc lợi 250tr | AV8: 658357000 | BH8: 658357000 | BJ8: 658357000 | BV8: 658357000
A9: 1 | B9: Lương và phúc lơi | D9: Chi phí phụ cấp Công tác phí | E9: Chi phí phụ cấp Công tác phí | F9: 32700000 | G9: 0 | H9: 2700000 | I9: 2000000 | J9: 2500000 | K9: 1500000 | L9: 4200000 | M9: 1500000 | N9: 2000000 | O9: 3000000 | P9: 4000000 | Q9: 4800000 | R9: 4500000 | S9: 0 | T9: 54600000 | U9: 0 | V9: 2700000 | W9: 2000000 | X9: 9600000 | Y9: 4500000 | Z9: 8700000 | AA9: 7900000 | AB9: 3600000 | AC9: 1000000 | AD9: 3000000 | AE9: 5600000 | AF9: 6000000 | AH9: 58400000 | AI9: 9000000 | AJ9: 900000 | AK9: 9600000 | AL9: 4500000 | AM9: 8700000 | AN9: 7900000 | AO9: 3600000 | AP9: 1000000 | AQ9: 3000000 | AR9: 5600000 | AS9: 3100000 | AT9: 1500000 | AU9: 0 | AV9: 36000000 | AW9: 3000000 | AX9: 3000000 | AY9: 3000000 | AZ9: 3000000 | BA9: 3000000 | BB9: 3000000 | BC9: 3000000 | BD9: 3000000 | BE9: 3000000 | BF9: 3000000 | BG9: 3000000 | BH9: 3000000 | BJ9: 36000000 | BK9: 3000000 | BL9: 3000000 | BM9: 3000000 | BN9: 3000000 | BO9: 3000000 | BP9: 3000000 | BQ9: 3000000 | BR9: 3000000 | BS9: 3000000 | BT9: 3000000 | BU9: 3000000 | BV9: 3000000
A10: 2 | B10: Lương và phúc lơi | D10: Thưởng Tết âm lịch | E10: Thưởng Tết âm lịch | F10: 0 | G10: 0 | H10: 0 | I10: 0 | J10: 0 | K10: 0 | L10: 0 | M10: 0 | N10: 0 | O10: 0 | P10: 0 | Q10: 0 | R10: 0 | S10: 0 | T10: 54000000 | U10: 0 | V10: 0 | W10: 0 | X10: 0 | Y10: 0 | Z10: 0 | AA10: 0 | AB10: 0 | AC10: 0 | AD10: 0 | AE10: 0 | AF10: 54000000 | AG10: KH nhân sự tại 31/12/24 là 28 người và 8 TV HĐQT BKS | AH10: 52000000 | AI10: 0 | AJ10: 0 | AK10: 0 | AL10: 0 | AM10: 0 | AN10: 0 | AO10: 0 | AP10: 0 | AQ10: 0 | AR10: 0 | AS10: 0 | AT10: 52000000 | AU10: 0 | AV10: 11000000 | AW10: 11000000 | BJ10: 11000000 | BK10: 11000000
A11: 2 | B11: Lương và phúc lơi | D11: Lương thâm niên | E11: Lương thâm niên | F11: 0 | G11: 0 | H11: 0 | I11: 0 | J11: 0 | K11: 0 | L11: 0 | M11: 0 | N11: 0 | O11: 0 | P11: 0 | Q11: 0 | R11: 0 | S11: 0 | T11: 0 | U11: 0 | V11: 0 | W11: 0 | X11: 0 | Y11: 0 | Z11: 0 | AA11: 0 | AB11: 0 | AC11: 0 | AD11: 0 | AE11: 0 | AF11: 0 | AH11: 47000000 | AI11: 0 | AJ11: 0 | AK11: 47000000 | AL11: 0 | AM11: 0 | AN11: 0 | AO11: 0 | AP11: 0 | AQ11: 0 | AR11: 0 | AS11: 0 | AT11: 0 | AU11: Thâm niên 2023 trả vào 2024 | AV11: 0 | BJ11: 0
A12: 2 | B12: Lương và phúc lơi | D12: Thưởng Tết dương lịch | E12: Thưởng Tết dương lịch | F12: 11000000 | G12: 0 | H12: 0 | I12: 0 | J12: 0 | K12: 0 | L12: 0 | M12: 0 | N12: 0 | O12: 0 | P12: 0 | Q12: 0 | R12: 11000000 | S12: 0 | T12: 54000000 | U12: 0 | V12: 0 | W12: 0 | X12: 0 | Y12: 0 | Z12: 0 | AA12: 0 | AB12: 0 | AC12: 0 | AD12: 0 | AE12: 0 | AF12: 54000000 | AH12: 52000000 | AI12: 0 | AJ12: 0 | AK12: 0 | AL12: 0 | AM12: 0 | AN12: 0 | AO12: 0 | AP12: 0 | AQ12: 0 | AR12: 0 | AS12: 0 | AT12: 52000000 | AU12: 0 | AV12: 11000000 | BH12: 11000000 | BJ12: 11000000 | BV12: 11000000
A13: 2 | B13: Lương và phúc lơi | D13: Thưởng 8/3 | E13: Thưởng 8/3 | F13: 8000000 | G13: 0 | H13: 8000000 | I13: 0 | J13: 0 | K13: 0 | L13: 0 | M13: 0 | N13: 0 | O13: 0 | P13: 0 | Q13: 0 | R13: 0 | S13: 0 | T13: 9000000 | U13: 0 | V13: 0 | W13: 9000000 | X13: 0 | Y13: 0 | Z13: 0 | AA13: 0 | AB13: 0 | AC13: 0 | AD13: 0 | AE13: 0 | AF13: 0 | AH13: 0 | AI13: 0 | AJ13: 0 | AK13: 0 | AL13: 0 | AM13: 0 | AN13: 0 | AO13: 0 | AP13: 0 | AQ13: 0 | AR13: 0 | AS13: 0 | AT13: 0 | AU13: 2024 là 9 triệu chi bằng quỹ phúc lợi | AV13: 2800000 | AY13: 2800000 | BJ13: 2800000 | BM13: 2800000
A14: 2 | B14: Lương và phúc lơi | D14: Thưởng 30/04-1/5 | E14: Thưởng 30/04-1/5 | F14: 47000000 | G14: 0 | H14: 0 | I14: 0 | J14: 47000000 | K14: 0 | L14: 0 | M14: 0 | N14: 0 | O14: 0 | P14: 0 | Q14: 0 | R14: 0 | S14: 0 | T14: 56000000 | U14: 0 | V14: 0 | W14: 0 | X14: 56000000 | Y14: 0 | Z14: 0 | AA14: 0 | AB14: 0 | AC14: 0 | AD14: 0 | AE14: 0 | AF14: 0 | AH14: 48000000 | AI14: 0 | AJ14: 0 | AK14: 0 | AL14: 48000000 | AM14: 0 | AN14: 0 | AO14: 0 | AP14: 0 | AQ14: 0 | AR14: 0 | AS14: 0 | AT14: 0 | AU14: 0 | AV14: 11000000 | AZ14: 11000000 | BJ14: 11000000 | BN14: 11000000
A15: 2 | B15: Lương và phúc lơi | D15: Sinh nhật CBNV | E15: Sinh nhật CBNV | F15: 10500000 | G15: 2500000 | H15: 1500000 | I15: 1000000 | J15: 0 | K15: 500000 | L15: 1000000 | M15: 0 | N15: 1000000 | O15: 1000000 | P15: 500000 | Q15: 500000 | R15: 1000000 | S15: 0 | T15: 17500000 | U15: 1500000 | V15: 1500000 | W15: 1000000 | X15: 1500000 | Y15: 1500000 | Z15: 1500000 | AA15: 1500000 | AB15: 1500000 | AC15: 1500000 | AD15: 1500000 | AE15: 1500000 | AF15: 1500000 | AH15: 11000000 | AI15: 2000000 | AJ15: 0 | AK15: 2500000 | AL15: 0 | AM15: 0 | AN15: 2500000 | AO15: 0 | AP15: 0 | AQ15: 2000000 | AR15: 1500000 | AS15: 500000 | AT15: 0 | AU15: 0 | AV15: 11500000 | AW15: 2500000 | AX15: 1500000 | AY15: 1000000 | AZ15: 500000 | BA15: 500000 | BB15: 1000000 | BC15: 500000 | BD15: 1000000 | BE15: 1000000 | BF15: 500000 | BG15: 500000 | BH15: 1000000 | BJ15: 11500000 | BK15: 2500000 | BL15: 1500000 | BM15: 1000000 | BN15: 500000 | BO15: 500000 | BP15: 1000000 | BQ15: 500000 | BR15: 1000000 | BS15: 1000000 | BT15: 500000 | BU15: 500000 | BV15: 1000000
A16: 2 | B16: Lương và phúc lơi | D16: Thưởng 2/9 | E16: Thưởng 2/9 | F16: 44000000 | G16: 0 | H16: 0 | I16: 0 | J16: 0 | K16: 0 | L16: 0 | M16: 0 | N16: 44000000 | O16: 0 | P16: 0 | Q16: 0 | R16: 0 | S16: 0 | T16: 54000000 | U16: 0 | V16: 0 | W16: 0 | X16: 0 | Y16: 0 | Z16: 0 | AA16: 0 | AB16: 0 | AC16: 54000000 | AD16: 0 | AE16: 0 | AF16: 0 | AH16: 55000000 | AI16: 0 | AJ16: 0 | AK16: 0 | AL16: 0 | AM16: 0 | AN16: 0 | AO16: 0 | AP16: 55000000 | AQ16: 0 | AR16: 0 | AS16: 0 | AT16: 0 | AU16: 0 | AV16: 11000000 | BE16: 11000000 | BJ16: 11000000 | BS16: 11000000
A17: 2 | B17: Lương và phúc lơi | D17: Thưởng 20/10 | E17: Thưởng 20/10 | F17: 7000000 | G17: 0 | H17: 0 | I17: 0 | J17: 0 | K17: 0 | L17: 0 | M17: 0 | N17: 0 | O17: 0 | P17: 7000000 | Q17: 0 | R17: 0 | S17: 0 | T17: 9500000 | U17: 0 | V17: 0 | W17: 0 | X17: 0 | Y17: 0 | Z17: 0 | AA17: 0 | AB17: 0 | AC17: 0 | AD17: 9500000 | AE17: 0 | AF17: 0 | AH17: 9500000 | AI17: 0 | AJ17: 0 | AK17: 0 | AL17: 0 | AM17: 0 | AN17: 0 | AO17: 0 | AP17: 0 | AQ17: 0 | AR17: 9500000 | AS17: 0 | AT17: 0 | AU17: 0 | AV17: 2800000 | BF17: 2800000 | BJ17: 2800000 | BT17: 2800000
B18: Lương và phúc lơi | C18: Các khoản trích theo lương: BHXH. BHYT. KP Công Đoàn | F18: 425087700 | G18: 40009850 | H18: 38601400 | I18: 39852400 | J18: 37314900 | K18: 37683350 | L18: 32590900 | M18: 34094900 | N18: 32789400 | O18: 32661400 | P18: 32661400 | Q18: 32661400 | R18: 34166400 | S18: 0 | T18: 478803800 | U18: 40009850 | V18: 38601400 | W18: 39852400 | X18: 41537350 | Y18: 44911350 | Z18: 44911350 | AA18: 38163350 | AB18: 38163350 | AC18: 38163350 | AD18: 38163350 | AE18: 38163350 | AF18: 38163350 | AH18: 467587700 | AI18: 41886850 | AJ18: 41676850 | AK18: 40172850 | AL18: 39422350 | AM18: 39422350 | AN18: 41067350 | AO18: 38247350 | AP18: 36602350 | AQ18: 36602350 | AR18: 38247350 | AS18: 38694850 | AT18: 35544850 | AU18: 0 | AV18: 442235800 | AW18: 34470900 | AX18: 34470900 | AY18: 37329400 | AZ18: 37329400 | BA18: 37329400 | BB18: 37329400 | BC18: 37329400 | BD18: 37329400 | BE18: 37329400 | BF18: 37329400 | BG18: 37329400 | BH18: 37329400 | BJ18: 442235800 | BK18: 34470900 | BL18: 34470900 | BM18: 37329400 | BN18: 37329400 | BO18: 37329400 | BP18: 37329400 | BQ18: 37329400 | BR18: 37329400 | BS18: 37329400 | BT18: 37329400 | BU18: 37329400 | BV18: 37329400
